<?xml version="1.0"?>
<mujoco model="jvrc1">

    <compiler angle="radian" meshdir="../meshes" texturedir="../meshes" />

    <size njmax="500" nconmax="100" />

    <option timestep="0.001" iterations="50" tolerance="1e-10" solver="Newton" jacobian="dense" cone="pyramidal" />

    <asset>
        <texture name="grid" type="2d" builtin="checker" rgb1=".1 .2 .3"
        rgb2=".2 .3 .4" width="300" height="300"/>
        <material name="grid" texture="grid" texrepeat="8 8" reflectance=".2"/>
    </asset>

    <worldbody>

        <geom size="100 100 .01" type="plane" material="grid"/>

        <light directional="false" diffuse="0.2 0.2 0.2" specular="0 0 0" pos="0 0 2" dir="0 0 -1" castshadow="false" />
        <light mode="targetbodycom" directional="false" diffuse=".8 .8 .8" specular="0.3 0.3 0.3" pos="0 0 4.0" dir="0 0 -1" />
        <!-- pelvis -->
        <body name="calf_l" pos="0 0 8">
            <freejoint name="root" />
            <geom type="box" size="1 1 2"/>
            
            <body name="foot_l" pos="0 0 -3">
                <joint name="ANKLE_L" type="hinge" pos="0 0 0" axis="0 1 0"/>
                <geom type="box" size="2 1 0.5"/>
            </body>
        </body>

    </worldbody>

</mujoco>